---
layout: default
title: Catching Multiple Exceptions Nested and Multiple `except` Blocks
parent: Handling Exceptions Gracefully
grand_parent: Exception Handling and Debugging
nav_order: 2
---
# Catching Multiple Exceptions: Nested and Multiple `except` Blocks

Exception handling is a crucial aspect of writing robust and reliable code. In Python, developers can catch and handle specific exceptions using the `try-except` block. When dealing with complex code, it is common to encounter multiple types of exceptions that need to be handled in different ways.

In this article, we will explore the concept of catching multiple exceptions in Python using nested and multiple `except` blocks. We will discuss the importance of this approach, its intricacies, and its relevance in everyday coding scenarios.

## The Importance of Catching Multiple Exceptions

As a developer, you want to ensure that your code handles unexpected situations gracefully. Catching multiple exceptions allows you to provide specific and appropriate error handling for different types of exceptions that may arise during the execution of your code.

Consider a situation where you are writing an application that reads data from a file and performs some operations on it. The file could be in various formats, such as CSV, JSON, or XML. Each format may have its own quirks and potential errors. By catching multiple exceptions, you can handle these format-specific errors and provide informative error messages to the user.

## Nested `except` Blocks

Python allows you to nest `except` blocks to handle different exceptions separately. This approach gives you fine-grained control over exception handling and allows you to provide specific error-handling logic for each exception type.

Let's take a look at an example to understand how nested `except` blocks work:

```python
try:
    # Some code that may raise exceptions
    ...
except ValueError:
    # Handling ValueError
    ...
except FileNotFoundError:
    # Handling FileNotFoundError
    ...
except Exception:
    # Catching any other exception
    ...
```

In the above example, if the code in the `try` block raises a `ValueError`, it will be caught and handled by the first `except` block. If the code raises a `FileNotFoundError`, it will be caught and handled by the second `except` block. Any other exceptions not explicitly caught by the previous `except` blocks will be caught and handled by the last `except` block.

By nesting `except` blocks, you can create a hierarchy of exception handling, where more specific exceptions are caught and handled before more general ones.

## Multiple `except` Blocks

Python also allows you to handle multiple exceptions in a single `except` block. This approach can be useful when different types of exceptions need to be handled in the same way.

Let's consider an example where you are writing a function that interacts with a web API. The function makes HTTP requests and needs to handle possible network-related exceptions, such as `ConnectionError`, `TimeoutError`, and `HTTPError`. Instead of writing separate `except` blocks for each exception, you can handle them together:

```python
try:
    # Make an HTTP request
    ...
except (ConnectionError, TimeoutError, HTTPError) as e:
    # Handling network-related exceptions
    ...
```

In the above example, if any of the listed exceptions occur, they will be caught and handled by the single `except` block. You can access the caught exception using the `as` keyword and handle it accordingly.

## Real-World Scenarios and Applications

Catching multiple exceptions using nested and multiple `except` blocks is especially relevant in real-world coding scenarios where complex systems interact and multiple types of errors might occur.

For example, in a web application, you might need to handle exceptions related to database connectivity, user input validation errors, and authentication failures. By catching and handling specific exceptions, you can provide informative feedback to users and ensure the application remains stable and responsive.

In data processing tasks, such as ETL (Extract, Transform, Load) pipelines, you may encounter exceptions related to data parsing, network connectivity, or system errors. Handling these exceptions individually allows you to gracefully handle each error type and prevent the entire pipeline from failing due to a single error.

By providing practical and relatable examples, we hope this article has helped you understand the significance of catching multiple exceptions using nested and multiple `except` blocks. Incorporating this knowledge into your Python coding practices will enable you to write more robust and reliable applications. Happy coding!